<robot name="onshape">
<link name="base">
<visual>
<origin xyz="0 0 0" rpy="0 -0 0" />
<geometry>
<mesh filename="package://ntu_arm_0115/meshes/base.stl"/>
</geometry>
<material name="base_material">
<color rgba="0.61568627450980395466 0.81176470588235294379 0.92941176470588238168 1.0"/>
</material>
</visual>
<collision>
<origin xyz="0 0 0" rpy="0 -0 0" />
<geometry>
<mesh filename="package://ntu_arm_0115/meshes/base.stl"/>
</geometry>
</collision>
<inertial>
<origin xyz="1.3302103289394080257e-17 -1.8792346695687117391e-17 0.39250504714250816773" rpy="0 0 0"/>
<mass value="11.084825628710413881" />
<inertia ixx="0.76032065909670731862" ixy="0"  ixz="0" iyy="0.81920282468684935129" iyz="0" izz="0.10228518482547134527" />
</inertial>
</link>

<link name="part1_">
<visual>
<origin xyz="-0.03111492111989181894 0.1415642730183608311 -0.086724745081983467543" rpy="-1.5707963267948976682 -1.3412915091581462918e-14 6.9388939039072299184e-18" />
<geometry>
<mesh filename="package://ntu_arm_0115/meshes/part1_.stl"/>
</geometry>
<material name="part1__material">
<color rgba="0.98039215686274505668 0.71372549019607844922 0.0039215686274509803377 1.0"/>
</material>
</visual>
<collision>
<origin xyz="-0.03111492111989181894 0.1415642730183608311 -0.086724745081983467543" rpy="-1.5707963267948976682 -1.3412915091581462918e-14 6.9388939039072299184e-18" />
<geometry>
<mesh filename="package://ntu_arm_0115/meshes/part1_.stl"/>
</geometry>
</collision>
<inertial>
<origin xyz="5.450536818683848761e-06 3.6881449127501575447e-06 -0.04605409654170248418" rpy="0 0 0"/>
<mass value="0.23934446997131439416" />
<inertia ixx="0.00015290331978685847529" ixy="1.7433326674190786237e-07"  ixz="-5.7200701236945864423e-08" iyy="0.00015319308546965263135" iyz="1.0553220139077411015e-08" izz="0.00015522319494757659672" />
</inertial>
</link>

<link name="part2_">
<visual>
<origin xyz="-0.084404576389152968785 0.038100000000004463629 0.0085238329805431556352" rpy="-1.5707963267948981123 -5.9334430867517404524e-15 -1.232595164407830946e-32" />
<geometry>
<mesh filename="package://ntu_arm_0115/meshes/part2_.stl"/>
</geometry>
<material name="part2__material">
<color rgba="0.2313725490196078538 0.38039215686274507888 0.7058823529411765163 1.0"/>
</material>
</visual>
<collision>
<origin xyz="-0.084404576389152968785 0.038100000000004463629 0.0085238329805431556352" rpy="-1.5707963267948981123 -5.9334430867517404524e-15 -1.232595164407830946e-32" />
<geometry>
<mesh filename="package://ntu_arm_0115/meshes/part2_.stl"/>
</geometry>
</collision>
<inertial>
<origin xyz="0.00064427007732389962591 3.8454778134994205274e-06 -0.013094935688362816656" rpy="0 0 0"/>
<mass value="0.12927375128311807684" />
<inertia ixx="0.00010127847176095519936" ixy="2.4279177823210054811e-10"  ixz="2.7201543558342058349e-06" iyy="0.00023245923086481307075" iyz="2.3472706547151037186e-09" izz="0.00024657044672492982665" />
</inertial>
</link>

<link name="part3_">
<visual>
<origin xyz="-0.046757833784822455669 0.038100000000003825251 -0.25439758953439600697" rpy="-1.570796326794896558 -1.5707963267948892305 0" />
<geometry>
<mesh filename="package://ntu_arm_0115/meshes/part3_.stl"/>
</geometry>
<material name="part3__material">
<color rgba="0.64705882352941179736 0.64705882352941179736 0.64705882352941179736 1.0"/>
</material>
</visual>
<collision>
<origin xyz="-0.046757833784822455669 0.038100000000003825251 -0.25439758953439600697" rpy="-1.570796326794896558 -1.5707963267948892305 0" />
<geometry>
<mesh filename="package://ntu_arm_0115/meshes/part3_.stl"/>
</geometry>
</collision>
<inertial>
<origin xyz="0.0080151151968596585223 1.3294110828336591634e-05 -0.041348905082374209918" rpy="0 0 0"/>
<mass value="0.45415995954612875529" />
<inertia ixx="0.00043138948171713629954" ixy="-3.5817439638711857667e-08"  ixz="1.5814568849233483081e-05" iyy="0.00055245941073864040984" iyz="-1.2604227906684505184e-07" izz="0.00047953746970519985126" />
</inertial>
</link>

<link name="part4_">
<visual>
<origin xyz="-0.04850000000037121145 0.038099999999998135358 0.10060000000045965507" rpy="-1.5707963267949061059 -2.9044505886808024896e-12 -6.9388939039072283776e-18" />
<geometry>
<mesh filename="package://ntu_arm_0115/meshes/part4_.stl"/>
</geometry>
<material name="part4__material">
<color rgba="0.97254901960784312376 0.52941176470588235947 0.0039215686274509803377 1.0"/>
</material>
</visual>
<collision>
<origin xyz="-0.04850000000037121145 0.038099999999998135358 0.10060000000045965507" rpy="-1.5707963267949061059 -2.9044505886808024896e-12 -6.9388939039072283776e-18" />
<geometry>
<mesh filename="package://ntu_arm_0115/meshes/part4_.stl"/>
</geometry>
</collision>
<inertial>
<origin xyz="0.00042816124338685562778 -3.5851892951493935513e-06 -0.10598589558396287469" rpy="0 0 0"/>
<mass value="0.4080770697880534148" />
<inertia ixx="0.0033734919637904208986" ixy="1.2787383805291414034e-07"  ixz="2.0989878915063296493e-05" iyy="0.0034806979418167318524" iyz="8.5043521109645939993e-08" izz="0.0003948324787684564293" />
</inertial>
</link>

<link name="part5_">
<visual>
<origin xyz="-0.35777460307719011201 0.038099999999995970423 -0.21946231979234401277" rpy="-1.570796326794896558 -1.570796326794896558 0" />
<geometry>
<mesh filename="package://ntu_arm_0115/meshes/part5_.stl"/>
</geometry>
<material name="part5__material">
<color rgba="0.64705882352941179736 0.64705882352941179736 0.64705882352941179736 1.0"/>
</material>
</visual>
<collision>
<origin xyz="-0.35777460307719011201 0.038099999999995970423 -0.21946231979234401277" rpy="-1.570796326794896558 -1.570796326794896558 0" />
<geometry>
<mesh filename="package://ntu_arm_0115/meshes/part5_.stl"/>
</geometry>
</collision>
<inertial>
<origin xyz="0.0081597568955206201124 -6.5749221442382163737e-06 -0.039294113922044626719" rpy="0 0 0"/>
<mass value="0.34326536780685706907" />
<inertia ixx="0.00027168127963102738868" ixy="2.2841935759853092421e-07"  ixz="1.0229998808064562766e-05" iyy="0.00034540142929574999897" iyz="-4.8309291127974296546e-09" izz="0.0002836649196135134182" />
</inertial>
</link>

<link name="part6_">
<visual>
<origin xyz="-0.054027012646597982748 -0.038164902501546416058 -0.39744061962525423226" rpy="1.5707963267949245356 2.18011219636342256e-12 -4.0389678347315804437e-28" />
<geometry>
<mesh filename="package://ntu_arm_0115/meshes/part6_.stl"/>
</geometry>
<material name="part6__material">
<color rgba="0.61568627450980395466 0.81176470588235294379 0.92941176470588238168 1.0"/>
</material>
</visual>
<collision>
<origin xyz="-0.054027012646597982748 -0.038164902501546416058 -0.39744061962525423226" rpy="1.5707963267949245356 2.18011219636342256e-12 -4.0389678347315804437e-28" />
<geometry>
<mesh filename="package://ntu_arm_0115/meshes/part6_.stl"/>
</geometry>
</collision>
<inertial>
<origin xyz="0.0003314379403626804832 1.7470606641471764231e-05 0.11796813714106048343" rpy="0 0 0"/>
<mass value="0.26238464858703042237" />
<inertia ixx="0.002007722233473360849" ixy="7.3422015520686625021e-07"  ixz="-7.5603267757755421925e-06" iyy="0.0020764202805319594697" iyz="2.7774414453098552085e-07" izz="0.00018760409156111550254" />
</inertial>
</link>

<link name="wrist_motor_left">
<visual>
<origin xyz="-0.17848573555458005502 -0.0076515810346040047385 -0.23244964209848789638" rpy="1.6136413689457704823 -1.570796326720664382 0" />
<geometry>
<mesh filename="package://ntu_arm_0115/meshes/wrist_motor_left.stl"/>
</geometry>
<material name="wrist_motor_left_material">
<color rgba="0.2313725490196078538 0.38039215686274507888 0.7058823529411765163 1.0"/>
</material>
</visual>
<collision>
<origin xyz="-0.17848573555458005502 -0.0076515810346040047385 -0.23244964209848789638" rpy="1.6136413689457704823 -1.570796326720664382 0" />
<geometry>
<mesh filename="package://ntu_arm_0115/meshes/wrist_motor_left.stl"/>
</geometry>
</collision>
<inertial>
<origin xyz="-0.0052374884142285206209 -0.00024674832734740144002 -0.032379692511782076636" rpy="0 0 0"/>
<mass value="0.19666527712074083345" />
<inertia ixx="0.000109042198372668407" ixy="-9.6708982316782290851e-07"  ixz="-3.6344700960130485859e-06" iyy="0.00013198633164912147503" iyz="-2.3997208619978637308e-07" izz="0.00010174825554535029087" />
</inertial>
</link>

<link name="wrist_left">
<visual>
<origin xyz="-0.19639964209848848053 -3.3029414703289461386e-07 -0.13464966971321604139" rpy="-1.5707963267840756583 -7.3591657380389106703e-11 0" />
<geometry>
<mesh filename="package://ntu_arm_0115/meshes/wrist_left.stl"/>
</geometry>
<material name="wrist_left_material">
<color rgba="0.97254901960784312376 0.52941176470588235947 0.0039215686274509803377 1.0"/>
</material>
</visual>
<collision>
<origin xyz="-0.19639964209848848053 -3.3029414703289461386e-07 -0.13464966971321604139" rpy="-1.5707963267840756583 -7.3591657380389106703e-11 0" />
<geometry>
<mesh filename="package://ntu_arm_0115/meshes/wrist_left.stl"/>
</geometry>
</collision>
<inertial>
<origin xyz="-0.00015174772567702610182 4.8379936526541977891e-05 -0.029465920222596132111" rpy="0 0 0"/>
<mass value="0.34701818149440494254" />
<inertia ixx="0.00025256704893226685806" ixy="8.1364649409735206162e-07"  ixz="3.658827504602377485e-07" iyy="0.00025318979560887518642" iyz="-6.0814437006136665175e-07" izz="0.00025054477825839057206" />
</inertial>
</link>

<link name="palm_left">
<visual>
<origin xyz="-0.19722464209870835261 0.018154145578368502401 0.068597118606430348975" rpy="1.5707963268057174577 7.3591657380389106703e-11 0" />
<geometry>
<mesh filename="package://ntu_arm_0115/meshes/palm_left.stl"/>
</geometry>
<material name="palm_left_material">
<color rgba="0.74901960784313725839 0.74901960784313725839 0.74901960784313725839 1.0"/>
</material>
</visual>
<collision>
<origin xyz="-0.19722464209870835261 0.018154145578368502401 0.068597118606430348975" rpy="1.5707963268057174577 7.3591657380389106703e-11 0" />
<geometry>
<mesh filename="package://ntu_arm_0115/meshes/palm_left.stl"/>
</geometry>
</collision>
<inertial>
<origin xyz="-0.0018518012368178016214 0.022084032845421274621 0.047672134556132714223" rpy="0 0 0"/>
<mass value="0.23942215735057509329" />
<inertia ixx="0.00022087422972641337481" ixy="5.9709601860826899823e-07"  ixz="1.7402480752146100784e-05" iyy="0.00028678474756761485097" iyz="-6.4955978377726827238e-06" izz="8.6018846184017836278e-05" />
</inertial>
</link>

<link name="thumb1">
<visual>
<origin xyz="0.20411680007022189876 0.019719216211212284989 -0.05046630171424464073" rpy="-1.5834840449173732679 -0.0033867907112139863414 5.5511469598982850059e-17" />
<geometry>
<mesh filename="package://ntu_arm_0115/meshes/thumb1.stl"/>
</geometry>
<material name="thumb1_material">
<color rgba="0.74901960784313725839 0.74901960784313725839 0.74901960784313725839 1.0"/>
</material>
</visual>
<collision>
<origin xyz="0.20411680007022189876 0.019719216211212284989 -0.05046630171424464073" rpy="-1.5834840449173732679 -0.0033867907112139863414 5.5511469598982850059e-17" />
<geometry>
<mesh filename="package://ntu_arm_0115/meshes/thumb1.stl"/>
</geometry>
</collision>
<inertial>
<origin xyz="0.025149219290471536148 -0.010772696322734639368 -0.0047477922878165577242" rpy="0 0 0"/>
<mass value="0.020068952929677565111" />
<inertia ixx="1.2632204578906994231e-06" ixy="1.3797626091626175173e-06"  ixz="-4.47116991276633668e-08" iyy="3.4009074530731473863e-06" iyz="2.2320473497482582755e-08" izz="3.8779500708196139704e-06" />
</inertial>
</link>

<link name="part2_thumb">
<visual>
<origin xyz="-0.024999999999999994449 0.0034999999999999974708 0" rpy="-1.570796326794896558 -2.1684043449710093495e-19 0" />
<geometry>
<mesh filename="package://ntu_arm_0115/meshes/part2_thumb.stl"/>
</geometry>
<material name="part2_thumb_material">
<color rgba="0.74901960784313725839 0.74901960784313725839 0.74901960784313725839 1.0"/>
</material>
</visual>
<collision>
<origin xyz="-0.024999999999999994449 0.0034999999999999974708 0" rpy="-1.570796326794896558 -2.1684043449710093495e-19 0" />
<geometry>
<mesh filename="package://ntu_arm_0115/meshes/part2_thumb.stl"/>
</geometry>
</collision>
<inertial>
<origin xyz="-0.012491021162966379696 -0.00095895168440905816879 -0.0047584233406898360577" rpy="0 0 0"/>
<mass value="0.0070423954211282918658" />
<inertia ixx="1.7265770388888660997e-07" ixy="-1.226171731132364525e-09"  ixz="-7.4997970276775650057e-10" iyy="3.9477195282909042779e-07" iyz="2.03067510896121955e-10" izz="3.162836729272022365e-07" />
</inertial>
</link>

<link name="part3_thumb">
<visual>
<origin xyz="-0.024999999999999980571 0.0034999999999999979045 0" rpy="-1.570796326794896558 2.168404344971008868e-19 0" />
<geometry>
<mesh filename="package://ntu_arm_0115/meshes/part3_thumb.stl"/>
</geometry>
<material name="part3_thumb_material">
<color rgba="0.74901960784313725839 0.74901960784313725839 0.74901960784313725839 1.0"/>
</material>
</visual>
<collision>
<origin xyz="-0.024999999999999980571 0.0034999999999999979045 0" rpy="-1.570796326794896558 2.168404344971008868e-19 0" />
<geometry>
<mesh filename="package://ntu_arm_0115/meshes/part3_thumb.stl"/>
</geometry>
</collision>
<inertial>
<origin xyz="-0.012688999655621606769 -0.00079596462560036114475 -0.0047606866692329373805" rpy="0 0 0"/>
<mass value="0.0065922685487463756823" />
<inertia ixx="1.3925458362274035128e-07" ixy="-9.9773215248299425272e-09"  ixz="2.6014451208852405462e-10" iyy="3.5895256880919134615e-07" iyz="2.0414394575711836447e-10" izz="3.0003887976704136794e-07" />
</inertial>
</link>

<joint name="thumb_3" type="revolute">
<origin xyz="-0.024999999999999938938 2.6020852139652106416e-18 0.00030000000000000859313" rpy="-2.5257573810222149578e-15 -2.9986863686603908086e-15 0.030761075900952554452" />
<parent link="part2_thumb" />
<child link="part3_thumb" />
<axis xyz="0 0 1"/>
<limit effort="1" velocity="20" />
<joint_properties friction="0.0"/>
</joint>

<joint name="thumb_l1" type="revolute">
<origin xyz="0.047942987277608067886 -0.023744735934561306268 0.00061243913553328532817" rpy="0.058402077805689386891 -0.00067265742999375458585 2.6875548939042297469" />
<parent link="thumb1" />
<child link="part2_thumb" />
<axis xyz="0 0 1"/>
<limit effort="1" velocity="20" />
<joint_properties friction="0.0"/>
</joint>

<joint name="thumb_0l" type="revolute">
<origin xyz="-0.030200000000361250374 0.02365384140866558238 0.027299999999999990941" rpy="4.5989157950545401523e-17 -8.4634495063655157005e-17 -1.1265675082023807185" />
<parent link="palm_left" />
<child link="thumb1" />
<axis xyz="0 0 1"/>
<limit effort="1" velocity="20" />
<joint_properties friction="0.0"/>
</joint>

<link name="part1_index">
<visual>
<origin xyz="-0.044999999999999998335 -0.0035000000000000308642 -0.0095000000000000084377" rpy="1.570796326794896558 -0 -1.4094628242311557642e-18" />
<geometry>
<mesh filename="package://ntu_arm_0115/meshes/part1_index.stl"/>
</geometry>
<material name="part1_index_material">
<color rgba="0.74901960784313725839 0.74901960784313725839 0.74901960784313725839 1.0"/>
</material>
</visual>
<collision>
<origin xyz="-0.044999999999999998335 -0.0035000000000000308642 -0.0095000000000000084377" rpy="1.570796326794896558 -0 -1.4094628242311557642e-18" />
<geometry>
<mesh filename="package://ntu_arm_0115/meshes/part1_index.stl"/>
</geometry>
</collision>
<inertial>
<origin xyz="-0.022954762417317992745 0.0010971684972455042484 -0.0047199718013326502977" rpy="0 0 0"/>
<mass value="0.013679765149717939415" />
<inertia ixx="3.230978794804849552e-07" ixy="1.3246510347662079568e-08"  ixz="4.6687994911164000228e-10" iyy="2.0250736010263839653e-06" iyz="-8.3807167780175958119e-10" izz="1.8890815693103685414e-06" />
</inertial>
</link>

<link name="part2_index">
<visual>
<origin xyz="-0.025000000000000022204 -0.0035000000000000308642 -0.0095000000000000014988" rpy="1.570796326794896558 -0 -3.252606517456513302e-19" />
<geometry>
<mesh filename="package://ntu_arm_0115/meshes/part2_index.stl"/>
</geometry>
<material name="part2_index_material">
<color rgba="0.74901960784313725839 0.74901960784313725839 0.74901960784313725839 1.0"/>
</material>
</visual>
<collision>
<origin xyz="-0.025000000000000022204 -0.0035000000000000308642 -0.0095000000000000014988" rpy="1.570796326794896558 -0 -3.252606517456513302e-19" />
<geometry>
<mesh filename="package://ntu_arm_0115/meshes/part2_index.stl"/>
</geometry>
</collision>
<inertial>
<origin xyz="-0.012524742353314188836 0.00099658477287297483199 -0.0047412943614430986053" rpy="0 0 0"/>
<mass value="0.0069721983933555987251" />
<inertia ixx="1.699992670207785138e-07" ixy="3.3148424851768028325e-10"  ixz="7.2599553622424316651e-10" iyy="3.8272243864524717823e-07" iyz="2.0817455136958107977e-10" izz="3.0488802873593580726e-07" />
</inertial>
</link>

<link name="part3_index">
<visual>
<origin xyz="-0.025000000000000008327 -0.0035000000000000031086 -0.0094999999999999945599" rpy="1.570796326794896558 2.7755575615628913511e-17 -1.084202172485504434e-19" />
<geometry>
<mesh filename="package://ntu_arm_0115/meshes/part3_index.stl"/>
</geometry>
<material name="part3_index_material">
<color rgba="0.74901960784313725839 0.74901960784313725839 0.74901960784313725839 1.0"/>
</material>
</visual>
<collision>
<origin xyz="-0.025000000000000008327 -0.0035000000000000031086 -0.0094999999999999945599" rpy="1.570796326794896558 2.7755575615628913511e-17 -1.084202172485504434e-19" />
<geometry>
<mesh filename="package://ntu_arm_0115/meshes/part3_index.stl"/>
</geometry>
</collision>
<inertial>
<origin xyz="-0.012774257659322846986 0.00082011298423009110214 -0.0047392409869184415339" rpy="0 0 0"/>
<mass value="0.0065479419851190425947" />
<inertia ixx="1.380407236584126457e-07" ixy="7.9725215822307999194e-09"  ixz="-2.6615088673817661275e-10" iyy="3.5120645166663660482e-07" iyz="2.0584518297600546475e-10" izz="2.9235514849775640399e-07" />
</inertial>
</link>

<joint name="index_3" type="revolute">
<origin xyz="-0.025000000000000022204 -5.5511151231257827021e-17 0.00030000000000000165423" rpy="-1.1661678567254063999e-15 1.0269562977782697999e-15 -0.0091030482579927112646" />
<parent link="part2_index" />
<child link="part3_index" />
<axis xyz="0 0 1"/>
<limit effort="1" velocity="20" />
<joint_properties friction="0.0"/>
</joint>

<joint name="index_2" type="revolute">
<origin xyz="-0.044999999999999991396 -2.7755575615628913511e-17 0.00030000000000001206257" rpy="5.7072402359636628001e-16 7.0221606307542334473e-15 0.00033760700254439971737" />
<parent link="part1_index" />
<child link="part2_index" />
<axis xyz="0 0 1"/>
<limit effort="1" velocity="20" />
<joint_properties friction="0.0"/>
</joint>

<joint name="index_0l" type="revolute">
<origin xyz="-0.037794115467265347597 0.023653841408573128557 0.097973458386107603602" rpy="-3.1063111291916780665 1.396153598907882154 0.035826030000769837347" />
<parent link="palm_left" />
<child link="part1_index" />
<axis xyz="0 0 1"/>
<limit effort="1" velocity="20" />
<joint_properties friction="0.0"/>
</joint>

<link name="part1_index_2">
<visual>
<origin xyz="-0.044999999999999998335 -0.003499999999999975353 -0.0094999999999999997641" rpy="1.570796326794896558 -2.584939414228211484e-26 3.5242768286001564515e-19" />
<geometry>
<mesh filename="package://ntu_arm_0115/meshes/part1_index.stl"/>
</geometry>
<material name="part1_index_material">
<color rgba="0.74901960784313725839 0.74901960784313725839 0.74901960784313725839 1.0"/>
</material>
</visual>
<collision>
<origin xyz="-0.044999999999999998335 -0.003499999999999975353 -0.0094999999999999997641" rpy="1.570796326794896558 -2.584939414228211484e-26 3.5242768286001564515e-19" />
<geometry>
<mesh filename="package://ntu_arm_0115/meshes/part1_index.stl"/>
</geometry>
</collision>
<inertial>
<origin xyz="-0.022954762417317992745 0.0010971684972455597595 -0.0047199718013326407567" rpy="0 0 0"/>
<mass value="0.013679765149717939415" />
<inertia ixx="3.230978794804849552e-07" ixy="1.3246510347662079568e-08"  ixz="4.6687994911164010568e-10" iyy="2.0250736010263839653e-06" iyz="-8.3807167780175968458e-10" izz="1.8890815693103689649e-06" />
</inertial>
</link>

<link name="part2_index_2">
<visual>
<origin xyz="-0.024999999999999980571 -0.0035000000000000031086 -0.0095000000000000014988" rpy="1.570796326794896558 -0 7.6216199843244119283e-23" />
<geometry>
<mesh filename="package://ntu_arm_0115/meshes/part2_index.stl"/>
</geometry>
<material name="part2_index_material">
<color rgba="0.74901960784313725839 0.74901960784313725839 0.74901960784313725839 1.0"/>
</material>
</visual>
<collision>
<origin xyz="-0.024999999999999980571 -0.0035000000000000031086 -0.0095000000000000014988" rpy="1.570796326794896558 -0 7.6216199843244119283e-23" />
<geometry>
<mesh filename="package://ntu_arm_0115/meshes/part2_index.stl"/>
</geometry>
</collision>
<inertial>
<origin xyz="-0.012524742353314147203 0.00099658477287300172021 -0.0047412943614430986053" rpy="0 0 0"/>
<mass value="0.0069721983933555987251" />
<inertia ixx="1.699992670207785138e-07" ixy="3.3148424851768043834e-10"  ixz="7.2599553622424326991e-10" iyy="3.8272243864524696647e-07" iyz="2.0817455136958113147e-10" izz="3.0488802873593591314e-07" />
</inertial>
</link>

<link name="part3_index_2">
<visual>
<origin xyz="-0.024999999999999994449 -0.0035000000000000031086 -0.0095000000000000014988" rpy="1.570796326794896558 -0 1.6426688351606866603e-22" />
<geometry>
<mesh filename="package://ntu_arm_0115/meshes/part3_index.stl"/>
</geometry>
<material name="part3_index_material">
<color rgba="0.74901960784313725839 0.74901960784313725839 0.74901960784313725839 1.0"/>
</material>
</visual>
<collision>
<origin xyz="-0.024999999999999994449 -0.0035000000000000031086 -0.0095000000000000014988" rpy="1.570796326794896558 -0 1.6426688351606866603e-22" />
<geometry>
<mesh filename="package://ntu_arm_0115/meshes/part3_index.stl"/>
</geometry>
</collision>
<inertial>
<origin xyz="-0.012774257659322831374 0.00082011298423009110214 -0.0047392409869184484728" rpy="0 0 0"/>
<mass value="0.0065479419851190425947" />
<inertia ixx="1.3804072365841269864e-07" ixy="7.9725215822308015738e-09"  ixz="-2.6615088673817283874e-10" iyy="3.5120645166663660482e-07" iyz="2.0584518297600569739e-10" izz="2.9235514849775640399e-07" />
</inertial>
</link>

<joint name="middle_3" type="revolute">
<origin xyz="-0.024999999999999994449 -2.7755575615628913511e-17 0.0002999999999999993232" rpy="-1.1102232088828691609e-16 -4.2519668424639794276e-22 2.7761139717539014307e-17" />
<parent link="part2_index_2" />
<child link="part3_index_2" />
<axis xyz="0 0 1"/>
<limit effort="1" velocity="20" />
<joint_properties friction="0.0"/>
</joint>

<joint name="middle_2" type="revolute">
<origin xyz="-0.044999999999999998335 5.5511151231257827021e-17 0.00030000000000000122055" rpy="1.0040972674714916617e-16 1.360734144852812329e-15 -0.0055915748978838291164" />
<parent link="part1_index_2" />
<child link="part2_index_2" />
<axis xyz="0 0 1"/>
<limit effort="1" velocity="20" />
<joint_properties friction="0.0"/>
</joint>

<joint name="middle_0l" type="revolute">
<origin xyz="-0.01601561267537052885 0.023653841408838000016 0.10499999999999995448" rpy="1.5707963267948485964 1.5647816952034190319 -1.5707963267830851173" />
<parent link="palm_left" />
<child link="part1_index_2" />
<axis xyz="0 0 1"/>
<limit effort="1" velocity="20" />
<joint_properties friction="0.0"/>
</joint>

<link name="part1_index_3">
<visual>
<origin xyz="-0.044999999999999991396 -0.0035000000000000308642 -0.0094999999999999980294" rpy="1.570796326794896558 -0 -1.8973538018496330003e-19" />
<geometry>
<mesh filename="package://ntu_arm_0115/meshes/part1_index.stl"/>
</geometry>
<material name="part1_index_material">
<color rgba="0.74901960784313725839 0.74901960784313725839 0.74901960784313725839 1.0"/>
</material>
</visual>
<collision>
<origin xyz="-0.044999999999999991396 -0.0035000000000000308642 -0.0094999999999999980294" rpy="1.570796326794896558 -0 -1.8973538018496330003e-19" />
<geometry>
<mesh filename="package://ntu_arm_0115/meshes/part1_index.stl"/>
</geometry>
</collision>
<inertial>
<origin xyz="-0.022954762417317989276 0.0010971684972455042484 -0.0047199718013326407567" rpy="0 0 0"/>
<mass value="0.013679765149717939415" />
<inertia ixx="3.2309787948048484932e-07" ixy="1.3246510347662069642e-08"  ixz="4.6687994911163989888e-10" iyy="2.0250736010263839653e-06" iyz="-8.3807167780175999478e-10" izz="1.8890815693103685414e-06" />
</inertial>
</link>

<link name="part2_index_3">
<visual>
<origin xyz="-0.025000000000000008327 -0.0035000000000000031086 -0.0095000000000000014988" rpy="1.570796326794896558 -1.3877787807814456755e-17 -7.8062556418956319249e-18" />
<geometry>
<mesh filename="package://ntu_arm_0115/meshes/part2_index.stl"/>
</geometry>
<material name="part2_index_material">
<color rgba="0.74901960784313725839 0.74901960784313725839 0.74901960784313725839 1.0"/>
</material>
</visual>
<collision>
<origin xyz="-0.025000000000000008327 -0.0035000000000000031086 -0.0095000000000000014988" rpy="1.570796326794896558 -1.3877787807814456755e-17 -7.8062556418956319249e-18" />
<geometry>
<mesh filename="package://ntu_arm_0115/meshes/part2_index.stl"/>
</geometry>
</collision>
<inertial>
<origin xyz="-0.012524742353314176693 0.00099658477287300172021 -0.0047412943614430986053" rpy="0 0 0"/>
<mass value="0.0069721983933555987251" />
<inertia ixx="1.699992670207785138e-07" ixy="3.3148424851768043834e-10"  ixz="7.2599553622424554466e-10" iyy="3.8272243864524696647e-07" iyz="2.0817455136958136411e-10" izz="3.0488802873593580726e-07" />
</inertial>
</link>

<link name="part3_index_3">
<visual>
<origin xyz="-0.025000000000000008327 -0.0035000000000000031086 -0.0094999999999999997641" rpy="1.570796326794896558 1.3877787807814456755e-17 2.4394548880923849765e-18" />
<geometry>
<mesh filename="package://ntu_arm_0115/meshes/part3_index.stl"/>
</geometry>
<material name="part3_index_material">
<color rgba="0.74901960784313725839 0.74901960784313725839 0.74901960784313725839 1.0"/>
</material>
</visual>
<collision>
<origin xyz="-0.025000000000000008327 -0.0035000000000000031086 -0.0094999999999999997641" rpy="1.570796326794896558 1.3877787807814456755e-17 2.4394548880923849765e-18" />
<geometry>
<mesh filename="package://ntu_arm_0115/meshes/part3_index.stl"/>
</geometry>
</collision>
<inertial>
<origin xyz="-0.012774257659322846986 0.00082011298423009023478 -0.0047392409869184458707" rpy="0 0 0"/>
<mass value="0.0065479419851190425947" />
<inertia ixx="1.380407236584126457e-07" ixy="7.9725215822307999194e-09"  ixz="-2.6615088673817071909e-10" iyy="3.5120645166663649894e-07" iyz="2.0584518297600574909e-10" izz="2.9235514849775650987e-07" />
</inertial>
</link>

<joint name="ring_3" type="revolute">
<origin xyz="-0.025000000000000008327 0 0.00029999999999999991951" rpy="-5.6898930012039509355e-16 2.9143354396410373977e-16 -0.05696095774989672067" />
<parent link="part2_index_3" />
<child link="part3_index_3" />
<axis xyz="0 0 1"/>
<limit effort="1" velocity="20" />
<joint_properties friction="0.0"/>
</joint>

<joint name="ring_2" type="revolute">
<origin xyz="-0.044999999999999991396 0 0.00029999999999999905215" rpy="8.6389229103645082049e-16 -2.942091015256722419e-15 0.099184374561439442308" />
<parent link="part1_index_3" />
<child link="part2_index_3" />
<axis xyz="0 0 1"/>
<limit effort="1" velocity="20" />
<joint_properties friction="0.0"/>
</joint>

<joint name="ring_0l" type="revolute">
<origin xyz="0.0032172278644303428652 0.023653841409072062785 0.097688573456416211149" rpy="-0.19993527106305714058 1.4817514776502944684 2.9408832597497411854" />
<parent link="palm_left" />
<child link="part1_index_3" />
<axis xyz="0 0 1"/>
<limit effort="1" velocity="20" />
<joint_properties friction="0.0"/>
</joint>

<link name="part1_index_4">
<visual>
<origin xyz="-0.044999999999999998335 -0.0035000000000000031086 -0.0095000000000000014988" rpy="1.570796326794896558 -0 -2.4123498337802473657e-18" />
<geometry>
<mesh filename="package://ntu_arm_0115/meshes/part1_index.stl"/>
</geometry>
<material name="part1_index_material">
<color rgba="0.74901960784313725839 0.74901960784313725839 0.74901960784313725839 1.0"/>
</material>
</visual>
<collision>
<origin xyz="-0.044999999999999998335 -0.0035000000000000031086 -0.0095000000000000014988" rpy="1.570796326794896558 -0 -2.4123498337802473657e-18" />
<geometry>
<mesh filename="package://ntu_arm_0115/meshes/part1_index.stl"/>
</geometry>
</collision>
<inertial>
<origin xyz="-0.022954762417317992745 0.001097168497245532004 -0.0047199718013326424915" rpy="0 0 0"/>
<mass value="0.013679765149717939415" />
<inertia ixx="3.230978794804849552e-07" ixy="1.3246510347662079568e-08"  ixz="4.6687994911164010568e-10" iyy="2.0250736010263839653e-06" iyz="-8.3807167780175968458e-10" izz="1.8890815693103689649e-06" />
</inertial>
</link>

<link name="part2_index_4">
<visual>
<origin xyz="-0.025000000000000008327 -0.003499999999999975353 -0.0094999999999999962946" rpy="1.570796326794896558 -0 -1.8973538018496327595e-19" />
<geometry>
<mesh filename="package://ntu_arm_0115/meshes/part2_index.stl"/>
</geometry>
<material name="part2_index_material">
<color rgba="0.74901960784313725839 0.74901960784313725839 0.74901960784313725839 1.0"/>
</material>
</visual>
<collision>
<origin xyz="-0.025000000000000008327 -0.003499999999999975353 -0.0094999999999999962946" rpy="1.570796326794896558 -0 -1.8973538018496327595e-19" />
<geometry>
<mesh filename="package://ntu_arm_0115/meshes/part2_index.stl"/>
</geometry>
</collision>
<inertial>
<origin xyz="-0.012524742353314176693 0.00099658477287302947578 -0.0047412943614430942685" rpy="0 0 0"/>
<mass value="0.0069721983933555987251" />
<inertia ixx="1.699992670207785138e-07" ixy="3.3148424851768012815e-10"  ixz="7.2599553622423892721e-10" iyy="3.8272243864524696647e-07" iyz="2.0817455136958110562e-10" izz="3.0488802873593580726e-07" />
</inertial>
</link>

<link name="part3_index_4">
<visual>
<origin xyz="-0.024999999999999994449 -0.0035000000000000031086 -0.0095000000000000014988" rpy="1.570796326794896558 -0 -1.1655173354219172666e-18" />
<geometry>
<mesh filename="package://ntu_arm_0115/meshes/part3_index.stl"/>
</geometry>
<material name="part3_index_material">
<color rgba="0.74901960784313725839 0.74901960784313725839 0.74901960784313725839 1.0"/>
</material>
</visual>
<collision>
<origin xyz="-0.024999999999999994449 -0.0035000000000000031086 -0.0095000000000000014988" rpy="1.570796326794896558 -0 -1.1655173354219172666e-18" />
<geometry>
<mesh filename="package://ntu_arm_0115/meshes/part3_index.stl"/>
</geometry>
</collision>
<inertial>
<origin xyz="-0.012774257659322834843 0.00082011298423009023478 -0.0047392409869184502075" rpy="0 0 0"/>
<mass value="0.0065479419851190425947" />
<inertia ixx="1.380407236584126457e-07" ixy="7.9725215822307999194e-09"  ixz="-2.6615088673817676785e-10" iyy="3.5120645166663649894e-07" iyz="2.0584518297600580079e-10" izz="2.9235514849775629811e-07" />
</inertial>
</link>

<joint name="pinky_3" type="revolute">
<origin xyz="-0.024999999999999966693 -8.3266726846886740532e-17 0.00029999999999998257227" rpy="1.7477339020466361058e-16 8.3266726846886703554e-17 0.043797405215435070147" />
<parent link="part2_index_4" />
<child link="part3_index_4" />
<axis xyz="0 0 1"/>
<limit effort="1" velocity="20" />
<joint_properties friction="0.0"/>
</joint>

<joint name="pinky_2" type="revolute">
<origin xyz="-0.044999999999999942824 2.7755575615628913511e-17 0.00029999999999991144861" rpy="-2.938187887435714551e-16 -3.3584246494911770264e-15 -0.0024763672993925217765" />
<parent link="part1_index_4" />
<child link="part2_index_4" />
<axis xyz="0 0 1"/>
<limit effort="1" velocity="20" />
<joint_properties friction="0.0"/>
</joint>

<joint name="pinky_0l" type="revolute">
<origin xyz="0.020658245684852478974 0.023653841409284281916 0.091143582929059108189" rpy="-0.13282365840352708397 1.482752380751304111 3.0082586081059274896" />
<parent link="palm_left" />
<child link="part1_index_4" />
<axis xyz="0 0 1"/>
<limit effort="1" velocity="20" />
<joint_properties friction="0.0"/>
</joint>

<joint name="lock_palm_left" type="revolute">
<origin xyz="2.2083563622840852749e-13 0.018153815284232266425 -0.066052551106785872825" rpy="3.141592653589793116 -2.5981348888728736239e-17 -9.1648802639172220347e-15" />
<parent link="wrist_left" />
<child link="palm_left" />
<axis xyz="0 0 1"/>
<limit effort="1" velocity="20" />
<joint_properties friction="0.0"/>
</joint>

<joint name="lock_wrist_left" type="revolute">
<origin xyz="-0.043959620829568779588 -0.0018846051361727789164 -0.036050000000079615581" rpy="-3.0987476114497320978 -1.5707963267916813521 0" />
<parent link="wrist_motor_left" />
<child link="wrist_left" />
<axis xyz="0 0 1"/>
<limit effort="1" velocity="20" />
<joint_properties friction="0.0"/>
</joint>

<joint name="lock_wrist_motor_left" type="revolute">
<origin xyz="0.036050000000567572478 -2.5615620735663924279e-13 0.23585000000006389742" rpy="-1.5707963267763451753 1.5283746760209737658 -1.570796326776353169" />
<parent link="part6_" />
<child link="wrist_motor_left" />
<axis xyz="0 0 1"/>
<limit effort="1" velocity="20" />
<joint_properties friction="0.0"/>
</joint>

<joint name="11" type="revolute">
<origin xyz="0.046499999999905117232 2.4147350785597154754e-15 -0.043000330300720077115" rpy="1.5707963268848783578 -1.5465967040365029561 1.5707963267060647272" />
<parent link="part5_" />
<child link="part6_" />
<axis xyz="0 0 1"/>
<limit effort="1" velocity="20" />
<joint_properties friction="0.0"/>
</joint>

<joint name="10" type="revolute">
<origin xyz="0.043000330300817561635 2.5812685322534889565e-15 -0.25150033030084917307" rpy="7.8687056870309089985e-15 1.570796320764467735 0" />
<parent link="part4_" />
<child link="part5_" />
<axis xyz="0 0 1"/>
<limit effort="1" velocity="20" />
<joint_properties friction="0.0"/>
</joint>

<joint name="9" type="revolute">
<origin xyz="0.052500000000601954042 4.7462034302725442103e-15 -0.043499999999985529409" rpy="1.5707963267084925629 -1.5465967040333368221 -1.5707963267084856795" />
<parent link="part3_" />
<child link="part4_" />
<axis xyz="0 0 1"/>
<limit effort="1" velocity="20" />
<joint_properties friction="0.0"/>
</joint>

<joint name="8" type="revolute">
<origin xyz="0.043500330300841383302 1.9984014443252817728e-15 -0.045100000000004469847" rpy="1.570796326794891673 -6.1043071242291172789e-07 1.5707963267949056618" />
<parent link="part2_" />
<child link="part3_" />
<axis xyz="0 0 1"/>
<limit effort="1" velocity="20" />
<joint_properties friction="0.0"/>
</joint>

<joint name="part1-2l" type="revolute">
<origin xyz="8.5695339713254270464e-16 1.2212453270876721945e-15 -0.073799999999872745171" rpy="5.0664760318955988011e-17 1.7254206980554951814e-18 -0.039512588747337568096" />
<parent link="part1_" />
<child link="part2_" />
<axis xyz="0 0 1"/>
<limit effort="1" velocity="20" />
<joint_properties friction="0.0"/>
</joint>

<joint name="lock_base_1l" type="revolute">
<origin xyz="0.077499999999999791278 -2.7061686225238190673e-16 0.76500000000000045741" rpy="-1.570796326794896558 0.039512588747337637485 1.570796326794896558" />
<parent link="base" />
<child link="part1_" />
<axis xyz="0 0 1"/>
<limit effort="1" velocity="20" />
<joint_properties friction="0.0"/>
</joint>

<link name="part1__2">
<visual>
<origin xyz="-0.03111492111989182241 0.1415642730183608311 -0.086724745081983467543" rpy="-1.5707963267948976682 -1.341291509158146134e-14 0" />
<geometry>
<mesh filename="package://ntu_arm_0115/meshes/part1_.stl"/>
</geometry>
<material name="part1__material">
<color rgba="0.98039215686274505668 0.71372549019607844922 0.0039215686274509803377 1.0"/>
</material>
</visual>
<collision>
<origin xyz="-0.03111492111989182241 0.1415642730183608311 -0.086724745081983467543" rpy="-1.5707963267948976682 -1.341291509158146134e-14 0" />
<geometry>
<mesh filename="package://ntu_arm_0115/meshes/part1_.stl"/>
</geometry>
</collision>
<inertial>
<origin xyz="5.450536818683848761e-06 3.6881449127224019691e-06 -0.04605409654170248418" rpy="0 0 0"/>
<mass value="0.23934446997131439416" />
<inertia ixx="0.0001529033197868585295" ixy="1.7433326674190791531e-07"  ixz="-5.720070123694587104e-08" iyy="0.00015319308546965268556" iyz="1.0553220139077412669e-08" izz="0.00015522319494757659672" />
</inertial>
</link>

<link name="part2__2">
<visual>
<origin xyz="-0.084404576389152954907 0.038100000000004352607 0.0085238329805431556352" rpy="-1.5707963267948981123 -5.9334430867517404524e-15 0" />
<geometry>
<mesh filename="package://ntu_arm_0115/meshes/part2_.stl"/>
</geometry>
<material name="part2__material">
<color rgba="0.2313725490196078538 0.38039215686274507888 0.7058823529411765163 1.0"/>
</material>
</visual>
<collision>
<origin xyz="-0.084404576389152954907 0.038100000000004352607 0.0085238329805431556352" rpy="-1.5707963267948981123 -5.9334430867517404524e-15 0" />
<geometry>
<mesh filename="package://ntu_arm_0115/meshes/part2_.stl"/>
</geometry>
</collision>
<inertial>
<origin xyz="0.0006442700773239135037 3.845477813388398225e-06 -0.013094935688362816656" rpy="0 0 0"/>
<mass value="0.12927375128311807684" />
<inertia ixx="0.00010127847176095519936" ixy="2.4279177823210054811e-10"  ixz="2.7201543558342058349e-06" iyy="0.00023245923086481307075" iyz="2.3472706547151037186e-09" izz="0.00024657044672492982665" />
</inertial>
</link>

<link name="part3__2">
<visual>
<origin xyz="-0.046757833784822344647 0.03810000000000376974 -0.25439758953439600697" rpy="-1.570796326794896558 -1.5707963267948892305 0" />
<geometry>
<mesh filename="package://ntu_arm_0115/meshes/part3_.stl"/>
</geometry>
<material name="part3__material">
<color rgba="0.64705882352941179736 0.64705882352941179736 0.64705882352941179736 1.0"/>
</material>
</visual>
<collision>
<origin xyz="-0.046757833784822344647 0.03810000000000376974 -0.25439758953439600697" rpy="-1.570796326794896558 -1.5707963267948892305 0" />
<geometry>
<mesh filename="package://ntu_arm_0115/meshes/part3_.stl"/>
</geometry>
</collision>
<inertial>
<origin xyz="0.0080151151968597556668 1.3294110828281080483e-05 -0.041348905082374209918" rpy="0 0 0"/>
<mass value="0.45415995954612875529" />
<inertia ixx="0.00043138948171713619112" ixy="-3.5817439638711811345e-08"  ixz="1.5814568849233479693e-05" iyy="0.00055245941073864040984" iyz="-1.2604227906684505184e-07" izz="0.00047953746970519985126" />
</inertial>
</link>

<link name="part4__2">
<visual>
<origin xyz="-0.048500000000371218389 0.038099999999998135358 0.10060000000045976609" rpy="-1.5707963267949061059 -2.9044505856118319584e-12 1.7347234759768067092e-18" />
<geometry>
<mesh filename="package://ntu_arm_0115/meshes/part4_.stl"/>
</geometry>
<material name="part4__material">
<color rgba="0.97254901960784312376 0.52941176470588235947 0.0039215686274509803377 1.0"/>
</material>
</visual>
<collision>
<origin xyz="-0.048500000000371218389 0.038099999999998135358 0.10060000000045976609" rpy="-1.5707963267949061059 -2.9044505856118319584e-12 1.7347234759768067092e-18" />
<geometry>
<mesh filename="package://ntu_arm_0115/meshes/part4_.stl"/>
</geometry>
</collision>
<inertial>
<origin xyz="0.00042816124338686256667 -3.5851892951424546574e-06 -0.10598589558396279142" rpy="0 0 0"/>
<mass value="0.4080770697880534148" />
<inertia ixx="0.0033734919637904226333" ixy="1.2787383805294945103e-07"  ixz="2.0989878915063303269e-05" iyy="0.003480697941816730985" iyz="8.5043521109647263482e-08" izz="0.00039483247876845653773" />
</inertial>
</link>

<link name="part5__2">
<visual>
<origin xyz="-0.35777460307718988997 0.038099999999995998179 -0.21946231979234395726" rpy="-1.570796326794896558 -1.570796326794896558 0" />
<geometry>
<mesh filename="package://ntu_arm_0115/meshes/part5_.stl"/>
</geometry>
<material name="part5__material">
<color rgba="0.64705882352941179736 0.64705882352941179736 0.64705882352941179736 1.0"/>
</material>
</visual>
<collision>
<origin xyz="-0.35777460307718988997 0.038099999999995998179 -0.21946231979234395726" rpy="-1.570796326794896558 -1.570796326794896558 0" />
<geometry>
<mesh filename="package://ntu_arm_0115/meshes/part5_.stl"/>
</geometry>
</collision>
<inertial>
<origin xyz="0.0081597568955207866459 -6.574922144217397998e-06 -0.039294113922044543452" rpy="0 0 0"/>
<mass value="0.34326536780685706907" />
<inertia ixx="0.00027168127963102728026" ixy="2.2841935759853126832e-07"  ixz="1.0229998808064562766e-05" iyy="0.00034540142929575010739" iyz="-4.8309291127973155037e-09" izz="0.00028366491961351352662" />
</inertial>
</link>

<link name="part6__2">
<visual>
<origin xyz="-0.054027012646597982748 0.038164902501546443814 0.39724061962525425429" rpy="-1.5707963267948688024 -2.1801121969982836801e-12 0" />
<geometry>
<mesh filename="package://ntu_arm_0115/meshes/part6_.stl"/>
</geometry>
<material name="part6__material">
<color rgba="0.61568627450980395466 0.81176470588235294379 0.92941176470588238168 1.0"/>
</material>
</visual>
<collision>
<origin xyz="-0.054027012646597982748 0.038164902501546443814 0.39724061962525425429" rpy="-1.5707963267948688024 -2.1801121969982836801e-12 0" />
<geometry>
<mesh filename="package://ntu_arm_0115/meshes/part6_.stl"/>
</geometry>
</collision>
<inertial>
<origin xyz="0.0003314379403626804832 -1.7470606641437069761e-05 -0.1181681371410604614" rpy="0 0 0"/>
<mass value="0.26238464858703042237" />
<inertia ixx="0.002007722233473360849" ixy="-7.3422015520686963834e-07"  ixz="7.5603267757755421925e-06" iyy="0.0020764202805319586023" iyz="2.7774414453098377384e-07" izz="0.00018760409156111550254" />
</inertial>
</link>

<link name="wrist_motor_right">
<visual>
<origin xyz="0.17848573555457997175 -0.0076515810346040047385 -0.23244964209848795189" rpy="1.6136413689457704823 1.570796326720664382 0" />
<geometry>
<mesh filename="package://ntu_arm_0115/meshes/wrist_motor_right.stl"/>
</geometry>
<material name="wrist_motor_right_material">
<color rgba="0.2313725490196078538 0.38039215686274507888 0.7058823529411765163 1.0"/>
</material>
</visual>
<collision>
<origin xyz="0.17848573555457997175 -0.0076515810346040047385 -0.23244964209848795189" rpy="1.6136413689457704823 1.570796326720664382 0" />
<geometry>
<mesh filename="package://ntu_arm_0115/meshes/wrist_motor_right.stl"/>
</geometry>
</collision>
<inertial>
<origin xyz="0.0052374900524378075958 -0.00024674932901223818127 -0.032379695155358351188" rpy="0 0 0"/>
<mass value="0.19666525526563508053" />
<inertia ixx="0.00010904218979175660123" ixy="9.6711388762484402974e-07"  ixz="3.634466869300831888e-06" iyy="0.00013198632073426144902" iyz="-2.3995392928034698089e-07" izz="0.00010174825659499731382" />
</inertial>
</link>

<link name="wrist_right">
<visual>
<origin xyz="0.19639964209848853605 -3.3029414703289461386e-07 -0.13464966971321601363" rpy="-1.5707963267840756583 7.3591657399028898023e-11 -3.4694469519536141888e-18" />
<geometry>
<mesh filename="package://ntu_arm_0115/meshes/wrist_right.stl"/>
</geometry>
<material name="wrist_right_material">
<color rgba="0.97254901960784312376 0.52941176470588235947 0.0039215686274509803377 1.0"/>
</material>
</visual>
<collision>
<origin xyz="0.19639964209848853605 -3.3029414703289461386e-07 -0.13464966971321601363" rpy="-1.5707963267840756583 7.3591657399028898023e-11 -3.4694469519536141888e-18" />
<geometry>
<mesh filename="package://ntu_arm_0115/meshes/wrist_right.stl"/>
</geometry>
</collision>
<inertial>
<origin xyz="0.00015175856780152985337 4.8375558304467466627e-05 -0.029465900835869713453" rpy="0 0 0"/>
<mass value="0.34701793815827475242" />
<inertia ixx="0.00025256695604661358757" ixy="-8.1362850582455204801e-07"  ixz="-3.6589390790620422125e-07" iyy="0.00025318958720346187129" iyz="-6.0818976909657234821e-07" izz="0.00025054469701824401764" />
</inertial>
</link>

<link name="palm_right">
<visual>
<origin xyz="0.19722464209870835261 0.018154145578368557912 0.068597118606430335097" rpy="1.5707963268057174577 -7.3591657399028898023e-11 1.7347234759768070944e-18" />
<geometry>
<mesh filename="package://ntu_arm_0115/meshes/palm_right.stl"/>
</geometry>
<material name="palm_right_material">
<color rgba="0.74901960784313725839 0.74901960784313725839 0.74901960784313725839 1.0"/>
</material>
</visual>
<collision>
<origin xyz="0.19722464209870835261 0.018154145578368557912 0.068597118606430335097" rpy="1.5707963268057174577 -7.3591657399028898023e-11 1.7347234759768070944e-18" />
<geometry>
<mesh filename="package://ntu_arm_0115/meshes/palm_right.stl"/>
</geometry>
</collision>
<inertial>
<origin xyz="0.0018518103379521200225 0.022084040636443404149 0.047672164500022706779" rpy="0 0 0"/>
<mass value="0.23942179131584503948" />
<inertia ixx="0.00022087395031012742189" ixy="-5.970814500971612594e-07"  ixz="-1.7402469425452821465e-05" iyy="0.00028678449884614174619" iyz="-6.4955528210117677984e-06" izz="8.6018856949810214405e-05" />
</inertial>
</link>

<link name="part1_index_5">
<visual>
<origin xyz="-0.044999999999999991396 -0.003499999999999975353 -0.0095000000000000049682" rpy="1.570796326794896558 -1.3877787807814456755e-17 8.3483567281383841419e-18" />
<geometry>
<mesh filename="package://ntu_arm_0115/meshes/part1_index.stl"/>
</geometry>
<material name="part1_index_material">
<color rgba="0.74901960784313725839 0.74901960784313725839 0.74901960784313725839 1.0"/>
</material>
</visual>
<collision>
<origin xyz="-0.044999999999999991396 -0.003499999999999975353 -0.0095000000000000049682" rpy="1.570796326794896558 -1.3877787807814456755e-17 8.3483567281383841419e-18" />
<geometry>
<mesh filename="package://ntu_arm_0115/meshes/part1_index.stl"/>
</geometry>
</collision>
<inertial>
<origin xyz="-0.022954762417317985806 0.0010971684972455597595 -0.0047199718013326459609" rpy="0 0 0"/>
<mass value="0.013679765149717939415" />
<inertia ixx="3.230978794804849552e-07" ixy="1.3246510347662072951e-08"  ixz="4.6687994911161828879e-10" iyy="2.0250736010263839653e-06" iyz="-8.3807167780175596227e-10" izz="1.8890815693103689649e-06" />
</inertial>
</link>

<link name="part2_index_5">
<visual>
<origin xyz="-0.024999999999999994449 -0.0035000000000000031086 -0.0094999999999999997641" rpy="1.570796326794896558 1.3877787807814456755e-17 -4.336808689942017736e-19" />
<geometry>
<mesh filename="package://ntu_arm_0115/meshes/part2_index.stl"/>
</geometry>
<material name="part2_index_material">
<color rgba="0.74901960784313725839 0.74901960784313725839 0.74901960784313725839 1.0"/>
</material>
</visual>
<collision>
<origin xyz="-0.024999999999999994449 -0.0035000000000000031086 -0.0094999999999999997641" rpy="1.570796326794896558 1.3877787807814456755e-17 -4.336808689942017736e-19" />
<geometry>
<mesh filename="package://ntu_arm_0115/meshes/part2_index.stl"/>
</geometry>
</collision>
<inertial>
<origin xyz="-0.012524742353314161081 0.00099658477287300172021 -0.0047412943614430977379" rpy="0 0 0"/>
<mass value="0.0069721983933555987251" />
<inertia ixx="1.699992670207785138e-07" ixy="3.3148424851768023155e-10"  ixz="7.2599553622424502767e-10" iyy="3.8272243864524696647e-07" iyz="2.0817455136958126071e-10" izz="3.0488802873593580726e-07" />
</inertial>
</link>

<link name="part3_index_5">
<visual>
<origin xyz="-0.025000000000000008327 -0.003499999999999975353 -0.0095000000000000032335" rpy="1.570796326794896558 -0 2.168404344971008868e-19" />
<geometry>
<mesh filename="package://ntu_arm_0115/meshes/part3_index.stl"/>
</geometry>
<material name="part3_index_material">
<color rgba="0.74901960784313725839 0.74901960784313725839 0.74901960784313725839 1.0"/>
</material>
</visual>
<collision>
<origin xyz="-0.025000000000000008327 -0.003499999999999975353 -0.0095000000000000032335" rpy="1.570796326794896558 -0 2.168404344971008868e-19" />
<geometry>
<mesh filename="package://ntu_arm_0115/meshes/part3_index.stl"/>
</geometry>
</collision>
<inertial>
<origin xyz="-0.012774257659322846986 0.00082011298423011799036 -0.0047392409869184502075" rpy="0 0 0"/>
<mass value="0.0065479419851190425947" />
<inertia ixx="1.380407236584126457e-07" ixy="7.972521582230798265e-09"  ixz="-2.6615088673816875454e-10" iyy="3.5120645166663649894e-07" iyz="2.0584518297600564569e-10" izz="2.9235514849775640399e-07" />
</inertial>
</link>

<joint name="index_r3" type="revolute">
<origin xyz="-0.024999999999999994449 -2.7755575615628913511e-17 0.00030000000000000425632" rpy="-1.9498291869979564177e-15 1.1796119636642329657e-15 0.0014286484754433028104" />
<parent link="part2_index_5" />
<child link="part3_index_5" />
<axis xyz="0 0 1"/>
<limit effort="1" velocity="20" />
<joint_properties friction="0.0"/>
</joint>

<joint name="pinky_r2" type="revolute">
<origin xyz="-0.044999999999999977518 -2.7755575615628913511e-17 0.00029999999999999384798" rpy="3.7643499428696028626e-16 -1.2351231148954696907e-15 0.031406461578478150898" />
<parent link="part1_index_5" />
<child link="part2_index_5" />
<axis xyz="0 0 1"/>
<limit effort="1" velocity="20" />
<joint_properties friction="0.0"/>
</joint>

<joint name="pinky_l1" type="revolute">
<origin xyz="-0.030719812135579234458 0.023653841409406739515 0.090263309927307619485" rpy="-2.7201841159308779439 1.4751388000903684627 0.42312148815437927718" />
<parent link="palm_right" />
<child link="part1_index_5" />
<axis xyz="0 0 1"/>
<limit effort="1" velocity="20" />
<joint_properties friction="0.0"/>
</joint>

<link name="part1_index_6">
<visual>
<origin xyz="-0.044999999999999991396 -0.0035000000000000031086 -0.0094999999999999980294" rpy="1.570796326794896558 1.3877787807814459837e-17 -8.3483567281383856826e-18" />
<geometry>
<mesh filename="package://ntu_arm_0115/meshes/part1_index.stl"/>
</geometry>
<material name="part1_index_material">
<color rgba="0.74901960784313725839 0.74901960784313725839 0.74901960784313725839 1.0"/>
</material>
</visual>
<collision>
<origin xyz="-0.044999999999999991396 -0.0035000000000000031086 -0.0094999999999999980294" rpy="1.570796326794896558 1.3877787807814459837e-17 -8.3483567281383856826e-18" />
<geometry>
<mesh filename="package://ntu_arm_0115/meshes/part1_index.stl"/>
</geometry>
</collision>
<inertial>
<origin xyz="-0.022954762417317989276 0.001097168497245532004 -0.004719971801332639022" rpy="0 0 0"/>
<mass value="0.013679765149717939415" />
<inertia ixx="3.2309787948048484932e-07" ixy="1.3246510347662069642e-08"  ixz="4.668799491116092932e-10" iyy="2.0250736010263839653e-06" iyz="-8.3807167780175968458e-10" izz="1.8890815693103689649e-06" />
</inertial>
</link>

<link name="part2_index_6">
<visual>
<origin xyz="-0.024999999999999994449 -0.003499999999999975353 -0.0094999999999999980294" rpy="1.570796326794896558 -0 0" />
<geometry>
<mesh filename="package://ntu_arm_0115/meshes/part2_index.stl"/>
</geometry>
<material name="part2_index_material">
<color rgba="0.74901960784313725839 0.74901960784313725839 0.74901960784313725839 1.0"/>
</material>
</visual>
<collision>
<origin xyz="-0.024999999999999994449 -0.003499999999999975353 -0.0094999999999999980294" rpy="1.570796326794896558 -0 0" />
<geometry>
<mesh filename="package://ntu_arm_0115/meshes/part2_index.stl"/>
</geometry>
</collision>
<inertial>
<origin xyz="-0.012524742353314161081 0.00099658477287302947578 -0.0047412943614430951358" rpy="0 0 0"/>
<mass value="0.0069721983933555987251" />
<inertia ixx="1.699992670207785138e-07" ixy="3.3148424851768012815e-10"  ixz="7.2599553622423903061e-10" iyy="3.8272243864524696647e-07" iyz="2.0817455136958061448e-10" izz="3.0488802873593591314e-07" />
</inertial>
</link>

<link name="part3_index_6">
<visual>
<origin xyz="-0.025000000000000022204 -0.0035000000000000308642 -0.0095000000000000032335" rpy="1.570796326794896558 -1.3877787807814456755e-17 2.168404344971008868e-19" />
<geometry>
<mesh filename="package://ntu_arm_0115/meshes/part3_index.stl"/>
</geometry>
<material name="part3_index_material">
<color rgba="0.74901960784313725839 0.74901960784313725839 0.74901960784313725839 1.0"/>
</material>
</visual>
<collision>
<origin xyz="-0.025000000000000022204 -0.0035000000000000308642 -0.0095000000000000032335" rpy="1.570796326794896558 -1.3877787807814456755e-17 2.168404344971008868e-19" />
<geometry>
<mesh filename="package://ntu_arm_0115/meshes/part3_index.stl"/>
</geometry>
</collision>
<inertial>
<origin xyz="-0.012774257659322862599 0.00082011298423006334657 -0.0047392409869184502075" rpy="0 0 0"/>
<mass value="0.0065479419851190425947" />
<inertia ixx="1.380407236584126457e-07" ixy="7.9725215822307999194e-09"  ixz="-2.6615088673817087419e-10" iyy="3.5120645166663660482e-07" iyz="2.0584518297600642118e-10" izz="2.9235514849775640399e-07" />
</inertial>
</link>

<joint name="middle_r3" type="revolute">
<origin xyz="-0.024999999999999952816 -2.7755575615628913511e-17 0.00030000000000001206257" rpy="-3.9551695252271226404e-16 5.8286708792820876144e-16 0.019262386864988042395" />
<parent link="part2_index_6" />
<child link="part3_index_6" />
<axis xyz="0 0 1"/>
<limit effort="1" velocity="20" />
<joint_properties friction="0.0"/>
</joint>

<joint name="middle_r2" type="revolute">
<origin xyz="-0.045000000000000005274 -2.7755575615628913511e-17 0.00030000000000000165423" rpy="2.6541269182445025285e-16 -1.1102230246251437214e-15 0.029549423757001775509" />
<parent link="part1_index_6" />
<child link="part2_index_6" />
<axis xyz="0 0 1"/>
<limit effort="1" velocity="20" />
<joint_properties friction="0.0"/>
</joint>

<joint name="ring_l1" type="revolute">
<origin xyz="-0.013278794315157070594 0.023653841409194603651 0.09680830045466481959" rpy="-2.720184115930813995 1.4751388000903664643 0.42312148815444511341" />
<parent link="palm_right" />
<child link="part1_index_6" />
<axis xyz="0 0 1"/>
<limit effort="1" velocity="20" />
<joint_properties friction="0.0"/>
</joint>

<link name="part1_index_7">
<visual>
<origin xyz="-0.044999999999999991396 -0.0035000000000000031086 -0.0094999999999999997641" rpy="1.570796326794896558 -0 1.9862922613113342951e-19" />
<geometry>
<mesh filename="package://ntu_arm_0115/meshes/part1_index.stl"/>
</geometry>
<material name="part1_index_material">
<color rgba="0.74901960784313725839 0.74901960784313725839 0.74901960784313725839 1.0"/>
</material>
</visual>
<collision>
<origin xyz="-0.044999999999999991396 -0.0035000000000000031086 -0.0094999999999999997641" rpy="1.570796326794896558 -0 1.9862922613113342951e-19" />
<geometry>
<mesh filename="package://ntu_arm_0115/meshes/part1_index.stl"/>
</geometry>
</collision>
<inertial>
<origin xyz="-0.022954762417317985806 0.001097168497245532004 -0.0047199718013326407567" rpy="0 0 0"/>
<mass value="0.013679765149717939415" />
<inertia ixx="3.230978794804849552e-07" ixy="1.3246510347662079568e-08"  ixz="4.6687994911164010568e-10" iyy="2.0250736010263839653e-06" iyz="-8.3807167780176299331e-10" izz="1.8890815693103689649e-06" />
</inertial>
</link>

<link name="part2_index_7">
<visual>
<origin xyz="-0.025000000000000022204 -0.003499999999999975353 -0.0095000000000000014988" rpy="1.570796326794896558 2.710505431213761085e-20 1.3844753522871539042e-18" />
<geometry>
<mesh filename="package://ntu_arm_0115/meshes/part2_index.stl"/>
</geometry>
<material name="part2_index_material">
<color rgba="0.74901960784313725839 0.74901960784313725839 0.74901960784313725839 1.0"/>
</material>
</visual>
<collision>
<origin xyz="-0.025000000000000022204 -0.003499999999999975353 -0.0095000000000000014988" rpy="1.570796326794896558 2.710505431213761085e-20 1.3844753522871539042e-18" />
<geometry>
<mesh filename="package://ntu_arm_0115/meshes/part2_index.stl"/>
</geometry>
</collision>
<inertial>
<origin xyz="-0.012524742353314188836 0.00099658477287302860842 -0.0047412943614430986053" rpy="0 0 0"/>
<mass value="0.0069721983933555987251" />
<inertia ixx="1.699992670207785138e-07" ixy="3.3148424851768105873e-10"  ixz="7.2599553622424326991e-10" iyy="3.8272243864524686059e-07" iyz="2.0817455136958190695e-10" izz="3.0488802873593591314e-07" />
</inertial>
</link>

<link name="part3_index_7">
<visual>
<origin xyz="-0.024999999999999966693 -0.0034999999999999475975 -0.0094999999999999980294" rpy="1.570796326794896558 -0 3.606454531171998039e-18" />
<geometry>
<mesh filename="package://ntu_arm_0115/meshes/part3_index.stl"/>
</geometry>
<material name="part3_index_material">
<color rgba="0.74901960784313725839 0.74901960784313725839 0.74901960784313725839 1.0"/>
</material>
</visual>
<collision>
<origin xyz="-0.024999999999999966693 -0.0034999999999999475975 -0.0094999999999999980294" rpy="1.570796326794896558 -0 3.606454531171998039e-18" />
<geometry>
<mesh filename="package://ntu_arm_0115/meshes/part3_index.stl"/>
</geometry>
</collision>
<inertial>
<origin xyz="-0.012774257659322808822 0.00082011298423014748066 -0.0047392409869184450033" rpy="0 0 0"/>
<mass value="0.0065479419851190425947" />
<inertia ixx="1.3804072365841259276e-07" ixy="7.9725215822307999194e-09"  ixz="-2.6615088673817278704e-10" iyy="3.512064516666367107e-07" iyz="2.0584518297600642118e-10" izz="2.9235514849775650987e-07" />
</inertial>
</link>

<joint name="ring_r3" type="revolute">
<origin xyz="-0.025000000000000022204 5.5511151231257827021e-17 0.00029999999999999861847" rpy="-8.1532003370910019719e-17 2.1182599944935613877e-15 0.026690786174408318715" />
<parent link="part2_index_7" />
<child link="part3_index_7" />
<axis xyz="0 0 1"/>
<limit effort="1" velocity="20" />
<joint_properties friction="0.0"/>
</joint>

<joint name="index_r2" type="revolute">
<origin xyz="-0.044999999999999998335 0 0.00029999999999999818479" rpy="1.2819606487469010691e-15 2.2405579995499412762e-15 -0.0068182458477929345012" />
<parent link="part1_index_7" />
<child link="part2_index_7" />
<axis xyz="0 0 1"/>
<limit effort="1" velocity="20" />
<joint_properties friction="0.0"/>
</joint>

<joint name="middle_l1" type="revolute">
<origin xyz="0.0059156126753704850116 0.023653841408960957216 0.10500000000000003775" rpy="-1.5707963267949549557 1.5658435345290870888 1.5707963267832274479" />
<parent link="palm_right" />
<child link="part1_index_7" />
<axis xyz="0 0 1"/>
<limit effort="1" velocity="20" />
<joint_properties friction="0.0"/>
</joint>

<link name="part1_index_8">
<visual>
<origin xyz="-0.044999999999999984457 -0.0035000000000000031086 -0.0094999999999999945599" rpy="1.570796326794896558 2.7755575615628913511e-17 1.3010426069826053208e-18" />
<geometry>
<mesh filename="package://ntu_arm_0115/meshes/part1_index.stl"/>
</geometry>
<material name="part1_index_material">
<color rgba="0.74901960784313725839 0.74901960784313725839 0.74901960784313725839 1.0"/>
</material>
</visual>
<collision>
<origin xyz="-0.044999999999999984457 -0.0035000000000000031086 -0.0094999999999999945599" rpy="1.570796326794896558 2.7755575615628913511e-17 1.3010426069826053208e-18" />
<geometry>
<mesh filename="package://ntu_arm_0115/meshes/part1_index.stl"/>
</geometry>
</collision>
<inertial>
<origin xyz="-0.022954762417317978868 0.0010971684972455311366 -0.0047199718013326355526" rpy="0 0 0"/>
<mass value="0.013679765149717939415" />
<inertia ixx="3.230978794804849552e-07" ixy="1.3246510347662074605e-08"  ixz="4.6687994911168363606e-10" iyy="2.0250736010263831183e-06" iyz="-8.3807167780175709965e-10" izz="1.8890815693103698119e-06" />
</inertial>
</link>

<link name="part2_index_8">
<visual>
<origin xyz="-0.024999999999999994449 -0.0035000000000000308642 -0.0095000000000000049682" rpy="1.570796326794896558 -0 -4.336808689942017736e-19" />
<geometry>
<mesh filename="package://ntu_arm_0115/meshes/part2_index.stl"/>
</geometry>
<material name="part2_index_material">
<color rgba="0.74901960784313725839 0.74901960784313725839 0.74901960784313725839 1.0"/>
</material>
</visual>
<collision>
<origin xyz="-0.024999999999999994449 -0.0035000000000000308642 -0.0095000000000000049682" rpy="1.570796326794896558 -0 -4.336808689942017736e-19" />
<geometry>
<mesh filename="package://ntu_arm_0115/meshes/part2_index.stl"/>
</geometry>
</collision>
<inertial>
<origin xyz="-0.012524742353314161081 0.00099658477287297396463 -0.0047412943614431020747" rpy="0 0 0"/>
<mass value="0.0069721983933555987251" />
<inertia ixx="1.699992670207785138e-07" ixy="3.3148424851768090363e-10"  ixz="7.2599553622423479131e-10" iyy="3.8272243864524696647e-07" iyz="2.0817455136958007164e-10" izz="3.0488802873593591314e-07" />
</inertial>
</link>

<link name="part3_index_8">
<visual>
<origin xyz="-0.024999999999999994449 -0.0035000000000000031086 -0.0094999999999999980294" rpy="1.570796326794896558 2.7755575615628907348e-17 8.6736173798840335461e-19" />
<geometry>
<mesh filename="package://ntu_arm_0115/meshes/part3_index.stl"/>
</geometry>
<material name="part3_index_material">
<color rgba="0.74901960784313725839 0.74901960784313725839 0.74901960784313725839 1.0"/>
</material>
</visual>
<collision>
<origin xyz="-0.024999999999999994449 -0.0035000000000000031086 -0.0094999999999999980294" rpy="1.570796326794896558 2.7755575615628907348e-17 8.6736173798840335461e-19" />
<geometry>
<mesh filename="package://ntu_arm_0115/meshes/part3_index.stl"/>
</geometry>
</collision>
<inertial>
<origin xyz="-0.012774257659322831374 0.00082011298423009110214 -0.0047392409869184450033" rpy="0 0 0"/>
<mass value="0.0065479419851190425947" />
<inertia ixx="1.3804072365841269864e-07" ixy="7.9725215822308015738e-09"  ixz="-2.6615088673817666445e-10" iyy="3.5120645166663660482e-07" iyz="2.0584518297600585249e-10" izz="2.9235514849775640399e-07" />
</inertial>
</link>

<joint name="pinky_r3" type="revolute">
<origin xyz="-0.025000000000000008327 0 0.00029999999999999818479" rpy="1.4918621893400531151e-16 -2.7755575615628921399e-15 0.012549840683073272898" />
<parent link="part2_index_8" />
<child link="part3_index_8" />
<axis xyz="0 0 1"/>
<limit effort="1" velocity="20" />
<joint_properties friction="0.0"/>
</joint>

<joint name="ring_r2" type="revolute">
<origin xyz="-0.045000000000000012212 2.7755575615628913511e-17 0.00030000000000001206257" rpy="-3.6776137690708147699e-16 -6.9388939039071987954e-16 -0.012369704938903988006" />
<parent link="part1_index_8" />
<child link="part2_index_8" />
<axis xyz="0 0 1"/>
<limit effort="1" velocity="20" />
<joint_properties friction="0.0"/>
</joint>

<joint name="index_l1" type="revolute">
<origin xyz="0.027847557161842128454 0.023653841408694198378 0.099727304980543635127" rpy="-0.05654529091142360131 1.3959811272393900516 3.0841741078337983062" />
<parent link="palm_right" />
<child link="part1_index_8" />
<axis xyz="0 0 1"/>
<limit effort="1" velocity="20" />
<joint_properties friction="0.0"/>
</joint>

<link name="thumb1_2">
<visual>
<origin xyz="0.20411680007022195427 0.019719216211212284989 -0.042966301714244641008" rpy="-1.5834840449173732679 -0.0033867907112139867751 5.5511469598982850059e-17" />
<geometry>
<mesh filename="package://ntu_arm_0115/meshes/thumb1.stl"/>
</geometry>
<material name="thumb1_material">
<color rgba="0.74901960784313725839 0.74901960784313725839 0.74901960784313725839 1.0"/>
</material>
</visual>
<collision>
<origin xyz="0.20411680007022195427 0.019719216211212284989 -0.042966301714244641008" rpy="-1.5834840449173732679 -0.0033867907112139867751 5.5511469598982850059e-17" />
<geometry>
<mesh filename="package://ntu_arm_0115/meshes/thumb1.stl"/>
</geometry>
</collision>
<inertial>
<origin xyz="0.02514921929047158819 -0.010772696322734639368 0.0027522077121834350594" rpy="0 0 0"/>
<mass value="0.020068952929677565111" />
<inertia ixx="1.2632204578906994231e-06" ixy="1.379762609162617729e-06"  ixz="-4.47116991276633668e-08" iyy="3.4009074530731473863e-06" iyz="2.2320473497482556285e-08" izz="3.8779500708196131234e-06" />
</inertial>
</link>

<link name="part2_thumb_2">
<visual>
<origin xyz="-0.024999999999999994449 0.003499999999999994435 0" rpy="-1.570796326794896558 -2.1684043449710093495e-19 0" />
<geometry>
<mesh filename="package://ntu_arm_0115/meshes/part2_thumb.stl"/>
</geometry>
<material name="part2_thumb_material">
<color rgba="0.74901960784313725839 0.74901960784313725839 0.74901960784313725839 1.0"/>
</material>
</visual>
<collision>
<origin xyz="-0.024999999999999994449 0.003499999999999994435 0" rpy="-1.570796326794896558 -2.1684043449710093495e-19 0" />
<geometry>
<mesh filename="package://ntu_arm_0115/meshes/part2_thumb.stl"/>
</geometry>
</collision>
<inertial>
<origin xyz="-0.012491021162966379696 -0.00095895168440906109614 -0.0047584233406898360577" rpy="0 0 0"/>
<mass value="0.0070423954211282918658" />
<inertia ixx="1.7265770388888660997e-07" ixy="-1.2261717311323651454e-09"  ixz="-7.4997970276775650057e-10" iyy="3.9477195282909053366e-07" iyz="2.0306751089612252368e-10" izz="3.162836729272022365e-07" />
</inertial>
</link>

<link name="part3_thumb_2">
<visual>
<origin xyz="-0.025000000000000022204 0.0034999999999999987718 6.9388939039072283776e-18" rpy="-1.570796326794896558 -2.1684043449710093495e-19 -3.4694469519536149592e-18" />
<geometry>
<mesh filename="package://ntu_arm_0115/meshes/part3_thumb.stl"/>
</geometry>
<material name="part3_thumb_material">
<color rgba="0.74901960784313725839 0.74901960784313725839 0.74901960784313725839 1.0"/>
</material>
</visual>
<collision>
<origin xyz="-0.025000000000000022204 0.0034999999999999987718 6.9388939039072283776e-18" rpy="-1.570796326794896558 -2.1684043449710093495e-19 -3.4694469519536149592e-18" />
<geometry>
<mesh filename="package://ntu_arm_0115/meshes/part3_thumb.stl"/>
</geometry>
</collision>
<inertial>
<origin xyz="-0.012688999655621650137 -0.00079596462560036027739 -0.0047606866692329304416" rpy="0 0 0"/>
<mass value="0.0065922685487463756823" />
<inertia ixx="1.3925458362274029834e-07" ixy="-9.9773215248299408728e-09"  ixz="2.6014451208852389952e-10" iyy="3.5895256880919134615e-07" iyz="2.0414394575711668426e-10" izz="3.0003887976704136794e-07" />
</inertial>
</link>

<joint name="thumb_r3" type="revolute">
<origin xyz="-0.024999999999999911182 -2.6888213877640509963e-17 0.00029999999999998083755" rpy="-3.198830089701269753e-15 -1.166601537594402278e-16 0.028924667986100816713" />
<parent link="part2_thumb_2" />
<child link="part3_thumb_2" />
<axis xyz="0 0 1"/>
<limit effort="1" velocity="20" />
<joint_properties friction="0.0"/>
</joint>

<joint name="thumb_r1" type="revolute">
<origin xyz="0.047942987277608095642 -0.02374473593456129239 0.0081124391355333128062" rpy="0.058402447207532265372 0.00063974299095168832979 2.6651096533697065105" />
<parent link="thumb1_2" />
<child link="part2_thumb_2" />
<axis xyz="0 0 1"/>
<limit effort="1" velocity="20" />
<joint_properties friction="0.0"/>
</joint>

<joint name="thumb_r0" type="revolute">
<origin xyz="0.030200000000361233027 0.023653841408665693402 0.027300000000000115841" rpy="-3.141592653589793116 -1.3419136407535058185e-15 -2.0239141129631872396" />
<parent link="palm_right" />
<child link="thumb1_2" />
<axis xyz="0 0 1"/>
<limit effort="1" velocity="20" />
<joint_properties friction="0.0"/>
</joint>

<joint name="lock_palm_right" type="revolute">
<origin xyz="-2.2077999151104421571e-13 0.018153815284232238669 -0.066052551106785858948" rpy="3.141592653589793116 -2.6847556296172312792e-17 1.0061396160665484845e-16" />
<parent link="wrist_right" />
<child link="palm_right" />
<axis xyz="0 0 1"/>
<limit effort="1" velocity="20" />
<joint_properties friction="0.0"/>
</joint>

<joint name="lock_wrist_right" type="revolute">
<origin xyz="0.043959620829568751832 -0.001884605136172806672 -0.036050000000079636397" rpy="-3.0987476114497320978 1.5707963267916886796 0" />
<parent link="wrist_motor_right" />
<child link="wrist_right" />
<axis xyz="0 0 1"/>
<limit effort="1" velocity="20" />
<joint_properties friction="0.0"/>
</joint>

<joint name="lock_wrist_motor_right" type="revolute">
<origin xyz="0.036050000000565116109 2.5632274081033301627e-13 -0.23605000000006204353" rpy="1.5707963268148821268 1.5314185258259067623 1.5707963268148588121" />
<parent link="part6__2" />
<child link="wrist_motor_right" />
<axis xyz="0 0 1"/>
<limit effort="1" velocity="20" />
<joint_properties friction="0.0"/>
</joint>

<joint name="5" type="revolute">
<origin xyz="0.046499999999905339276 2.4702462297909733024e-15 -0.043000330300720049359" rpy="-1.5707963266973119509 -1.5484823017965145819 1.5707963266985200956" />
<parent link="part5__2" />
<child link="part6__2" />
<axis xyz="0 0 1"/>
<limit effort="1" velocity="20" />
<joint_properties friction="0.0"/>
</joint>

<joint name="4" type="revolute">
<origin xyz="0.043000330300817547757 2.60902410786911787e-15 -0.25150033030084928409" rpy="1.5707963268229421239 1.5685698960520828571 1.5707963268190525685" />
<parent link="part4__2" />
<child link="part5__2" />
<axis xyz="0 0 1"/>
<limit effort="1" velocity="20" />
<joint_properties friction="0.0"/>
</joint>

<joint name="3" type="revolute">
<origin xyz="0.052500000000602065064 4.6629367034256574698e-15 -0.043499999999985446142" rpy="1.5707963265880813264 -1.5606871371915136404 -1.5707963265889863802" />
<parent link="part3__2" />
<child link="part4__2" />
<axis xyz="0 0 1"/>
<limit effort="1" velocity="20" />
<joint_properties friction="0.0"/>
</joint>

<joint name="2" type="revolute">
<origin xyz="0.043500330300841390241 2.1094237467877974268e-15 -0.045100000000004442091" rpy="-1.570796326794891673 0.0023725965824944084299 -1.570796326794886788" />
<parent link="part2__2" />
<child link="part3__2" />
<axis xyz="0 0 1"/>
<limit effort="1" velocity="20" />
<joint_properties friction="0.0"/>
</joint>

<joint name="part1-2r" type="revolute">
<origin xyz="2.8588242884097780916e-15 -4.4408920985006261617e-16 -0.073799999999872578638" rpy="-4.8714829772598056713e-20 1.109930529876681147e-16 -1.2143064331837232119e-17" />
<parent link="part1__2" />
<child link="part2__2" />
<axis xyz="0 0 1"/>
<limit effort="1" velocity="20" />
<joint_properties friction="0.0"/>
</joint>

<joint name="lock_base_1r" type="revolute">
<origin xyz="-0.077500000000000013323 4.1633363423443370266e-17 0.76500000000000012434" rpy="1.570796326794896558 -0 1.570796326794896558" />
<parent link="base" />
<child link="part1__2" />
<axis xyz="0 0 1"/>
<limit effort="1" velocity="20" />
<joint_properties friction="0.0"/>
</joint>


</robot>
